Workbook

Sheet dim_customers
A1: customer_id | B1: signup_date | C1: customer_segment | D1: city_tier | E1: lifetime_rewards_tier
A2: CUST_00001 | B2: 45985 | C2: Value Hunter | D2: Tier-2 Emerging | E2: Bronze
A3: CUST_00002 | B3: 45715 | C3: Bulk Buyer | D3: Tier-1 Metro | E3: Bronze
A4: CUST_00003 | B4: 45670 | C4: Premium Organic | D4: Tier-1 Metro | E4: Bronze
A5: CUST_00004 | B5: 45798 | C5: Convenience Seeker | D5: Tier-1 Metro | E5: Bronze
A6: CUST_00005 | B6: 45783 | C6: Value Hunter | D6: Tier-1 Metro | E6: Silver
A7: CUST_00006 | B7: 45772 | C7: Value Hunter | D7: Tier-2 Emerging | E7: Silver
A8: CUST_00007 | B8: 45729 | C8: Value Hunter | D8: Tier-1 Metro | E8: Bronze
A9: CUST_00008 | B9: 45710 | C9: Premium Organic | D9: Tier-1 Metro | E9: Bronze
A10: CUST_00009 | B10: 46004 | C10: Convenience Seeker | D10: Tier-1 Metro | E10: Platinum
A11: CUST_00010 | B11: 45937 | C11: Premium Organic | D11: Tier-2 Emerging | E11: Bronze
A12: CUST_00011 | B12: 45702 | C12: Value Hunter | D12: Tier-1 Metro | E12: Silver
A13: CUST_00012 | B13: 45960 | C13: Bulk Buyer | D13: Tier-1 Metro | E13: Bronze
... A1201: CUST_01200 | B1201: 45831 | C1201: Value Hunter | D1201: Tier-1 Metro | E1201: Silver

Sheet dim_darkstores
A1: hub_id | B1: hub_name | C1: city | D1: daily_operating_cost | E1: target_sla_minutes
A2: HUB_01 | B2: Indiranagar Express | C2: Bangalore | D2: 32000 | E2: 15
A3: HUB_02 | B3: Koramangala Darkstore | C3: Bangalore | D3: 35000 | E3: 15
A4: HUB_03 | B4: Whitefield Hub | C4: Bangalore | D4: 28000 | E4: 20
A5: HUB_04 | B5: Bandra Core | C5: Mumbai | D5: 42000 | E5: 15
A6: HUB_05 | B6: Andheri Logistics | C6: Mumbai | D6: 39000 | E6: 20
A7: HUB_06 | B7: Powai Fulfillment | C7: Mumbai | D7: 31000 | E7: 20
A8: HUB_07 | B8: Gurugram Sector-29 | C8: Delhi NCR | D8: 36000 | E8: 15
A9: HUB_08 | B9: Noida Hub 18 | C9: Delhi NCR | D9: 29000 | E9: 20
A10: HUB_09 | B10: South Ex Express | C10: Delhi NCR | D10: 33000 | E10: 15
A11: HUB_10 | B11: Hitec City Depot | C11: Hyderabad | D11: 30000 | E11: 15
A12: HUB_11 | B12: Gachibowli Logistics | C12: Hyderabad | D12: 27000 | E12: 20
A13: HUB_12 | B13: Kothrud Express | C13: Pune | D13: 24000 | E13: 20
... A16: HUB_15 | B16: Salt Lake Terminal | C16: Kolkata | D16: 25000 | E16: 20

Sheet dim_products
A1: product_id | B1: product_name | C1: category | D1: unit_cost | E1: listing_price
A2: SKU_0001 | B2: Personal Care 1 | C2: Personal Care | D2: 422.07 | E2: 653.68
A3: SKU_0002 | B3: Frozen Food 2 | C3: Instant & Frozen Foods | D3: 71.69 | E3: 93.09
A4: SKU_0003 | B4: Personal Care 3 | C4: Personal Care | D4: 452.99 | E4: 732.4
A5: SKU_0004 | B5: Beverage Snack 4 | C5: Snacks & Beverages | D5: 172.66 | E5: 253.7
A6: SKU_0005 | B6: Home Clean 5 | C6: Household & Cleaning | D6: 406.1 | E6: 607.19
A7: SKU_0006 | B7: Personal Care 6 | C7: Personal Care | D7: 372.31 | E7: 617.56
A8: SKU_0007 | B8: Staples Pack 7 | C8: Staples & Grains | D8: 260.77 | E8: 303.05
A9: SKU_0008 | B9: Beverage Snack 8 | C9: Snacks & Beverages | D9: 65.98 | E9: 87.73
A10: SKU_0009 | B10: Staples Pack 9 | C10: Staples & Grains | D10: 149.59 | E10: 179.12
A11: SKU_0010 | B11: Home Clean 10 | C11: Household & Cleaning | D11: 356.54 | E11: 563.89
A12: SKU_0011 | B12: Personal Care 11 | C12: Personal Care | D12: 105.81 | E12: 151.65
A13: SKU_0012 | B13: Dairy Baked 12 | C13: Dairy & Bakery | D13: 92.38 | E13: 102.02
... A251: SKU_0250 | B251: Dairy Baked 250 | C251: Dairy & Bakery | D251: 201.36 | E251: 228.56

Sheet fact_orders
A1: order_id | B1: customer_id | C1: product_id | D1: hub_id | E1: order_timestamp | F1: delivered_timestamp | G1: order_status | H1: quantity | I1: gross_sales | J1: item_cost | K1: promo_discount | L1: delivery_fee_charged | M1: actual_delivery_cost | N1: payment_gateway_fee | O1: payment_method | P1: sla_delay_minutes | Q1: customer_rating | R1: net_sales | S1: cm1_gross_margin | T1: net_logistics_cost | U1: cm2_variable_profit | V1: cm2_margin_pct | W1: is_profitable_order
A2: ORD_000001 | B2: CUST_00162 | C2: SKU_0238 | D2: HUB_02 | E2: 45658.296 | F2: 45658.305 | G2: DELIVERED | H2: 3 | I2: 2801.34 | J2: 2549.94 | K2: 700.34 | L2: 0 | M2: 48.96 | N2: 37.82 | O2: Cash on Delivery | P2: 0 | Q2: 5 | R2: =I2-K2 -> 2101 | S2: =R2-J2 -> -448.94 | T2: =L2-M2 -> -48.96 | U2: =S2+T2-N2 -> -535.72 | V2: =IF(R2>0, U2/R2, 0) -> -0.25498334 | W2: =IF(U2>0, 1, 0) -> 0
A3: ORD_000002 | B3: CUST_00351 | C3: SKU_0010 | D3: HUB_03 | E3: 45658.486 | F3: 45658.5 | G3: DELIVERED | H3: 1 | I3: 563.89 | J3: 356.54 | K3: 84.58 | L3: 0 | M3: 58.86 | N3: 8.63 | O3: Debit Card | P3: 0 | Q3: 5 | R3: =I3-K3 -> 479.31 | S3: =R3-J3 -> 122.77 | T3: =L3-M3 -> -58.86 | U3: =S3+T3-N3 -> 55.28 | V3: =IF(R3>0, U3/R3, 0) -> 0.11533246 | W3: =IF(U3>0, 1, 0) -> 1
A4: ORD_000003 | B4: CUST_00434 | C4: SKU_0152 | D4: HUB_08 | E4: 45658.502 | F4: 45658.512 | G4: DELIVERED | H4: 2 | I4: 912.82 | J4: 638.92 | K4: 45.64 | L4: 0 | M4: 61.96 | N4: 15.61 | O4: UPI | P4: 0 | Q4: 5 | R4: =I4-K4 -> 867.18 | S4: =R4-J4 -> 228.26 | T4: =L4-M4 -> -61.96 | U4: =S4+T4-N4 -> 150.69 | V4: =IF(R4>0, U4/R4, 0) -> 0.17377015 | W4: =IF(U4>0, 1, 0) -> 1
A5: ORD_000004 | B5: CUST_00852 | C5: SKU_0061 | D5: HUB_03 | E5: 45658.716 | F5: 45658.727 | G5: DELIVERED | H5: 1 | I5: 235.64 | J5: 162.24 | K5: 0 | L5: 30 | M5: 51.85 | N5: 4.78 | O5: UPI | P5: 0 | Q5: 4 | R5: =I5-K5 -> 235.64 | S5: =R5-J5 -> 73.4 | T5: =L5-M5 -> -21.85 | U5: =S5+T5-N5 -> 46.77 | V5: =IF(R5>0, U5/R5, 0) -> 0.19848073 | W5: =IF(U5>0, 1, 0) -> 1
A6: ORD_000005 | B6: CUST_00140 | C6: SKU_0238 | D6: HUB_07 | E6: 45658.784 | F6: 45658.789 | G6: DELIVERED | H6: 1 | I6: 933.78 | J6: 849.98 | K6: 140.07 | L6: 0 | M6: 46.57 | N6: 14.29 | O6: UPI | P6: 0 | Q6: 5 | R6: =I6-K6 -> 793.71 | S6: =R6-J6 -> -56.27 | T6: =L6-M6 -> -46.57 | U6: =S6+T6-N6 -> -117.13 | V6: =IF(R6>0, U6/R6, 0) -> -0.14757279 | W6: =IF(U6>0, 1, 0) -> 0
A7: ORD_000006 | B7: CUST_01156 | C7: SKU_0018 | D7: HUB_10 | E7: 45658.801 | F7: 45658.809 | G7: DELIVERED | H7: 1 | I7: 72.87 | J7: 55.17 | K7: 0 | L7: 30 | M7: 53.05 | N7: 1.85 | O7: UPI | P7: 0 | Q7: 5 | R7: =I7-K7 -> 72.87 | S7: =R7-J7 -> 17.7 | T7: =L7-M7 -> -23.05 | U7: =S7+T7-N7 -> -7.2 | V7: =IF(R7>0, U7/R7, 0) -> -0.098806093 | W7: =IF(U7>0, 1, 0) -> 0
A8: ORD_000007 | B8: CUST_00087 | C8: SKU_0086 | D8: HUB_14 | E8: 45658.824 | F8: 45658.841 | G8: RETURNED | H8: 1 | I8: 289.4 | J8: 173.32 | K8: 28.94 | L8: 30 | M8: 50.82 | N8: 5.23 | O8: UPI | P8: 9 | Q8: 1 | R8: =I8-K8 -> 260.46 | S8: =R8-J8 -> 87.14 | T8: =L8-M8 -> -20.82 | U8: =S8+T8-N8 -> 61.09 | V8: =IF(R8>0, U8/R8, 0) -> 0.23454657 | W8: =IF(U8>0, 1, 0) -> 1
A9: ORD_000008 | B9: CUST_00183 | C9: SKU_0137 | D9: HUB_10 | E9: 45658.826 | F9: 45658.847 | G9: DELIVERED | H9: 2 | I9: 327.6 | J9: 266.98 | K9: 32.76 | L9: 30 | M9: 38.09 | N9: 5.85 | O9: Cash on Delivery | P9: 16 | Q9: 2 | R9: =I9-K9 -> 294.84 | S9: =R9-J9 -> 27.86 | T9: =L9-M9 -> -8.09 | U9: =S9+T9-N9 -> 13.92 | V9: =IF(R9>0, U9/R9, 0) -> 0.047212047 | W9: =IF(U9>0, 1, 0) -> 1
A10: ORD_000009 | B10: CUST_00368 | C10: SKU_0145 | D10: HUB_09 | E10: 45658.839 | F10: 45658.855 | G10: DELIVERED | H10: 1 | I10: 21.98 | J10: 18.04 | K10: 3.3 | L10: 30 | M10: 43.34 | N10: 0.88 | O10: UPI | P10: 9 | Q10: 3 | R10: =I10-K10 -> 18.68 | S10: =R10-J10 -> 0.64 | T10: =L10-M10 -> -13.34 | U10: =S10+T10-N10 -> -13.58 | V10: =IF(R10>0, U10/R10, 0) -> -0.72698073 | W10: =IF(U10>0, 1, 0) -> 0
A11: ORD_000010 | B11: CUST_00129 | C11: SKU_0230 | D11: HUB_13 | E11: 45658.876 | F11: 45658.892 | G11: DELIVERED | H11: 4 | I11: 2630.6 | J11: 1737.24 | K11: 131.53 | L11: 0 | M11: 53.24 | N11: 44.98 | O11: Credit Card | P11: 3 | Q11: 4 | R11: =I11-K11 -> 2499.07 | S11: =R11-J11 -> 761.83 | T11: =L11-M11 -> -53.24 | U11: =S11+T11-N11 -> 663.61 | V11: =IF(R11>0, U11/R11, 0) -> 0.26554278 | W11: =IF(U11>0, 1, 0) -> 1
A12: ORD_000011 | B12: CUST_00670 | C12: SKU_0128 | D12: HUB_08 | E12: 45658.93 | F12: 45658.944 | G12: RETURNED | H12: 2 | I12: 1015.48 | J12: 700.78 | K12: 101.55 | L12: 0 | M12: 61.5 | N12: 16.45 | O12: Credit Card | P12: 0 | Q12: 1 | R12: =I12-K12 -> 913.93 | S12: =R12-J12 -> 213.15 | T12: =L12-M12 -> -61.5 | U12: =S12+T12-N12 -> 135.2 | V12: =IF(R12>0, U12/R12, 0) -> 0.14793256 | W12: =IF(U12>0, 1, 0) -> 1
A13: ORD_000012 | B13: CUST_00149 | C13: SKU_0104 | D13: HUB_01 | E13: 45658.942 | F13: 45658.948 | G13: DELIVERED | H13: 2 | I13: 150.58 | J13: 124.92 | K13: 22.59 | L13: 30 | M13: 60.8 | N13: 2.84 | O13: UPI | P13: 0 | Q13: 5 | R13: =I13-K13 -> 127.99 | S13: =R13-J13 -> 3.07 | T13: =L13-M13 -> -30.8 | U13: =S13+T13-N13 -> -30.57 | V13: =IF(R13>0, U13/R13, 0) -> -0.23884678 | W13: =IF(U13>0, 1, 0) -> 0
... A24: ORD_000023 | B24: CUST_00975 | C24: SKU_0025 | D24: HUB_06 | E24: 45659.735 | F24: 45659.746 | G24: DELIVERED | H24: 1 | I24: 241.16 | J24: 178.02 | K24: 12.06 | L24: 30 | M24: 47.64 | N24: 4.66 | O24: UPI | P24: 0 | Q24: 5 | R24: =I24-K24 -> 229.1 | S24: =R24-J24 -> 51.08 | T24: =L24-M24 -> -17.64 | U24: =S24+T24-N24 -> 28.78 | V24: =IF(R24>0, U24/R24, 0) -> 0.125622 | W24: =IF(U24>0, 1, 0) -> 1
A25: ORD_000024 | B25: CUST_01049 | C25: SKU_0139 | D25: HUB_01 | E25: 45659.816 | G25: CANCELLED | H25: 2 | I25: 375.14 | J25: 336.92 | K25: 56.27 | L25: 30 | M25: 38.72 | N25: 0 | O25: UPI | P25: 11 | R25: =I25-K25 -> 318.87 | S25: =R25-J25 -> -18.05 | T25: =L25-M25 -> -8.72 | U25: =S25+T25-N25 -> -26.77 | V25: =IF(R25>0, U25/R25, 0) -> -0.083952708 | W25: =IF(U25>0, 1, 0) -> 0
A26: ORD_000025 | B26: CUST_00789 | C26: SKU_0044 | D26: HUB_13 | E26: 45659.824 | F26: 45659.839 | G26: DELIVERED | H26: 4 | I26: 399.6 | J26: 260.76 | K26: 0 | L26: 0 | M26: 40.13 | N26: 7.19 | O26: UPI | P26: 2 | Q26: 4 | R26: =I26-K26 -> 399.6 | S26: =R26-J26 -> 138.84 | T26: =L26-M26 -> -40.13 | U26: =S26+T26-N26 -> 91.52 | V26: =IF(R26>0, U26/R26, 0) -> 0.22902903 | W26: =IF(U26>0, 1, 0) -> 1
A27: ORD_000026 | B27: CUST_00984 | C27: SKU_0014 | D27: HUB_15 | E27: 45659.904 | F27: 45659.918 | G27: DELIVERED | H27: 1 | I27: 294.16 | J27: 199.8 | K27: 44.12 | L27: 30 | M27: 44.81 | N27: 5.04 | O27: UPI | P27: 0 | Q27: 5 | R27: =I27-K27 -> 250.04 | S27: =R27-J27 -> 50.24 | T27: =L27-M27 -> -14.81 | U27: =S27+T27-N27 -> 30.39 | V27: =IF(R27>0, U27/R27, 0) -> 0.12154055 | W27: =IF(U27>0, 1, 0) -> 1
A28: ORD_000027 | B28: CUST_00889 | C28: SKU_0237 | D28: HUB_06 | E28: 45660.37 | F28: 45660.385 | G28: DELIVERED | H28: 1 | I28: 738.97 | J28: 669.94 | K28: 0 | L28: 0 | M28: 46.49 | N28: 13.3 | O28: Debit Card | P28: 1 | Q28: 4 | R28: =I28-K28 -> 738.97 | S28: =R28-J28 -> 69.03 | T28: =L28-M28 -> -46.49 | U28: =S28+T28-N28 -> 9.24 | V28: =IF(R28>0, U28/R28, 0) -> 0.012503891 | W28: =IF(U28>0, 1, 0) -> 1
A29: ORD_000028 | B29: CUST_00890 | C29: SKU_0029 | D29: HUB_14 | E29: 45660.448 | F29: 45660.457 | G29: DELIVERED | H29: 1 | I29: 147.56 | J29: 101.59 | K29: 0 | L29: 30 | M29: 52.29 | N29: 3.2 | O29: UPI | P29: 0 | Q29: 4 | R29: =I29-K29 -> 147.56 | S29: =R29-J29 -> 45.97 | T29: =L29-M29 -> -22.29 | U29: =S29+T29-N29 -> 20.48 | V29: =IF(R29>0, U29/R29, 0) -> 0.138791 | W29: =IF(U29>0, 1, 0) -> 1
A30: ORD_000029 | B30: CUST_00070 | C30: SKU_0074 | D30: HUB_04 | E30: 45660.486 | F30: 45660.499 | G30: DELIVERED | H30: 1 | I30: 269.53 | J30: 195.85 | K30: 40.43 | L30: 30 | M30: 43.55 | N30: 4.66 | O30: Credit Card | P30: 4 | Q30: 3 | R30: =I30-K30 -> 229.1 | S30: =R30-J30 -> 33.25 | T30: =L30-M30 -> -13.55 | U30: =S30+T30-N30 -> 15.04 | V30: =IF(R30>0, U30/R30, 0) -> 0.065648189 | W30: =IF(U30>0, 1, 0) -> 1
A31: ORD_000030 | B31: CUST_00625 | C31: SKU_0050 | D31: HUB_04 | E31: 45660.5 | F31: 45660.513 | G31: DELIVERED | H31: 1 | I31: 76.73 | J31: 62.02 | K31: 11.51 | L31: 30 | M31: 54.31 | N31: 1.71 | O31: Credit Card | P31: 4 | Q31: 3 | R31: =I31-K31 -> 65.22 | S31: =R31-J31 -> 3.2 | T31: =L31-M31 -> -24.31 | U31: =S31+T31-N31 -> -22.82 | V31: =IF(R31>0, U31/R31, 0) -> -0.34989267 | W31: =IF(U31>0, 1, 0) -> 0
A32: ORD_000031 | B32: CUST_00875 | C32: SKU_0240 | D32: HUB_14 | E32: 45660.515 | F32: 45660.521 | G32: DELIVERED | H32: 3 | I32: 1617.3 | J32: 1412.76 | K32: 161.73 | L32: 0 | M32: 60.68 | N32: 26.2 | O32: Debit Card | P32: 0 | Q32: 5 | R32: =I32-K32 -> 1455.57 | S32: =R32-J32 -> 42.81 | T32: =L32-M32 -> -60.68 | U32: =S32+T32-N32 -> -44.07 | V32: =IF(R32>0, U32/R32, 0) -> -0.030276799 | W32: =IF(U32>0, 1, 0) -> 0
A33: ORD_000032 | B33: CUST_01136 | C33: SKU_0005 | D33: HUB_02 | E33: 45660.522 | F33: 45660.534 | G33: DELIVERED | H33: 3 | I33: 1821.57 | J33: 1218.3 | K33: 455.39 | L33: 0 | M33: 64.64 | N33: 24.59 | O33: Cash on Delivery | P33: 2 | Q33: 4 | R33: =I33-K33 -> 1366.18 | S33: =R33-J33 -> 147.88 | T33: =L33-M33 -> -64.64 | U33: =S33+T33-N33 -> 58.65 | V33: =IF(R33>0, U33/R33, 0) -> 0.042929921 | W33: =IF(U33>0, 1, 0) -> 1
A34: ORD_000033 | B34: CUST_00471 | C34: SKU_0200 | D34: HUB_13 | E34: 45660.547 | F34: 45660.567 | G34: DELIVERED | H34: 2 | I34: 1595.64 | J34: 1386.34 | K34: 159.56 | L34: 0 | M34: 62.35 | N34: 25.85 | O34: UPI | P34: 9 | Q34: 3 | R34: =I34-K34 -> 1436.08 | S34: =R34-J34 -> 49.74 | T34: =L34-M34 -> -62.35 | U34: =S34+T34-N34 -> -38.46 | V34: =IF(R34>0, U34/R34, 0) -> -0.026781238 | W34: =IF(U34>0, 1, 0) -> 0
A35: ORD_000034 | B35: CUST_00091 | C35: SKU_0110 | D35: HUB_11 | E35: 45660.567 | F35: 45660.588 | G35: DELIVERED | H35: 1 | I35: 111.9 | J35: 79.15 | K35: 0 | L35: 30 | M35: 43.53 | N35: 2.55 | O35: Net Banking | P35: 10 | Q35: 3 | R35: =I35-K35 -> 111.9 | S35: =R35-J35 -> 32.75 | T35: =L35-M35 -> -13.53 | U35: =S35+T35-N35 -> 16.67 | V35: =IF(R35>0, U35/R35, 0) -> 0.1489723 | W35: =IF(U35>0, 1, 0) -> 1
A36: ORD_000035 | B36: CUST_00530 | C36: SKU_0197 | D36: HUB_14 | E36: 45660.594 | F36: 45660.607 | G36: DELIVERED | H36: 3 | I36: 614.13 | J36: 411.81 | K36: 30.71 | L36: 0 | M36: 60.25 | N36: 10.5 | O36: UPI | P36: 4 | Q36: 4 | R36: =I36-K36 -> 583.42 | S36: =R36-J36 -> 171.61 | T36: =L36-M36 -> -60.25 | U36: =S36+T36-N36 -> 100.86 | V36: =IF(R36>0, U36/R36, 0) -> 0.17287717 | W36: =IF(U36>0, 1, 0) -> 1
A37: ORD_000036 | B37: CUST_00661 | C37: SKU_0122 | D37: HUB_04 | E37: 45660.649 | F37: 45660.655 | G37: DELIVERED | H37: 2 | I37: 1617.58 | J37: 1434.22 | K37: 80.88 | L37: 0 | M37: 47.08 | N37: 27.66 | O37: Debit Card | P37: 0 | Q37: 5 | R37: =I37-K37 -> 1536.7 | S37: =R37-J37 -> 102.48 | T37: =L37-M37 -> -47.08 | U37: =S37+T37-N37 -> 27.74 | V37: =IF(R37>0, U37/R37, 0) -> 0.018051669 | W37: =IF(U37>0, 1, 0) -> 1
... A73: ORD_000072 | B73: CUST_00857 | C73: SKU_0191 | D73: HUB_06 | E73: 45662.643 | F73: 45662.654 | G73: DELIVERED | H73: 2 | I73: 383.66 | J73: 239.24 | K73: 0 | L73: 30 | M73: 63.02 | N73: 7.45 | O73: UPI | P73: 0 | Q73: 5 | R73: =I73-K73 -> 383.66 | S73: =R73-J73 -> 144.42 | T73: =L73-M73 -> -33.02 | U73: =S73+T73-N73 -> 103.95 | V73: =IF(R73>0, U73/R73, 0) -> 0.27094302 | W73: =IF(U73>0, 1, 0) -> 1
A74: ORD_000073 | B74: CUST_00897 | C74: SKU_0042 | D74: HUB_08 | E74: 45662.658 | G74: CANCELLED | H74: 2 | I74: 211.66 | J74: 152.46 | K74: 31.75 | L74: 30 | M74: 61.04 | N74: 0 | O74: Credit Card | P74: 11 | R74: =I74-K74 -> 179.91 | S74: =R74-J74 -> 27.45 | T74: =L74-M74 -> -31.04 | U74: =S74+T74-N74 -> -3.59 | V74: =IF(R74>0, U74/R74, 0) -> -0.019954422 | W74: =IF(U74>0, 1, 0) -> 0
A75: ORD_000074 | B75: CUST_00278 | C75: SKU_0064 | D75: HUB_15 | E75: 45662.76 | F75: 45662.774 | G75: DELIVERED | H75: 1 | I75: 204.1 | J75: 164.4 | K75: 30.62 | L75: 30 | M75: 42.79 | N75: 3.66 | O75: UPI | P75: 0 | Q75: 5 | R75: =I75-K75 -> 173.48 | S75: =R75-J75 -> 9.08 | T75: =L75-M75 -> -12.79 | U75: =S75+T75-N75 -> -7.37 | V75: =IF(R75>0, U75/R75, 0) -> -0.042483283 | W75: =IF(U75>0, 1, 0) -> 0
A76: ORD_000075 | B76: CUST_00552 | C76: SKU_0182 | D76: HUB_13 | E76: 45662.778 | F76: 45662.796 | G76: RETURNED | H76: 1 | I76: 423.08 | J76: 388.35 | K76: 21.15 | L76: 0 | M76: 58.55 | N76: 7.23 | O76: UPI | P76: 7 | Q76: 1 | R76: =I76-K76 -> 401.93 | S76: =R76-J76 -> 13.58 | T76: =L76-M76 -> -58.55 | U76: =S76+T76-N76 -> -52.2 | V76: =IF(R76>0, U76/R76, 0) -> -0.12987336 | W76: =IF(U76>0, 1, 0) -> 0
A77: ORD_000076 | B77: CUST_00111 | C77: SKU_0078 | D77: HUB_07 | E77: 45662.782 | F77: 45662.795 | G77: DELIVERED | H77: 1 | I77: 58.68 | J77: 44.37 | K77: 5.87 | L77: 30 | M77: 38.32 | N77: 1.49 | O77: UPI | P77: 4 | Q77: 3 | R77: =I77-K77 -> 52.81 | S77: =R77-J77 -> 8.44 | T77: =L77-M77 -> -8.32 | U77: =S77+T77-N77 -> -1.37 | V77: =IF(R77>0, U77/R77, 0) -> -0.025942056 | W77: =IF(U77>0, 1, 0) -> 0
A78: ORD_000077 | B78: CUST_00385 | C78: SKU_0127 | D78: HUB_03 | E78: 45662.831 | F78: 45662.843 | G78: DELIVERED | H78: 1 | I78: 30.14 | J78: 23.96 | K78: 4.52 | L78: 30 | M78: 63.41 | N78: 1 | O78: Net Banking | P78: 0 | Q78: 5 | R78: =I78-K78 -> 25.62 | S78: =R78-J78 -> 1.66 | T78: =L78-M78 -> -33.41 | U78: =S78+T78-N78 -> -32.75 | V78: =IF(R78>0, U78/R78, 0) -> -1.2782982 | W78: =IF(U78>0, 1, 0) -> 0
A79: ORD_000078 | B79: CUST_00761 | C79: SKU_0205 | D79: HUB_08 | E79: 45662.85 | F79: 45662.874 | G79: DELIVERED | H79: 1 | I79: 172.15 | J79: 149.53 | K79: 8.61 | L79: 30 | M79: 37.25 | N79: 3.48 | O79: UPI | P79: 14 | Q79: 3 | R79: =I79-K79 -> 163.54 | S79: =R79-J79 -> 14.01 | T79: =L79-M79 -> -7.25 | U79: =S79+T79-N79 -> 3.28 | V79: =IF(R79>0, U79/R79, 0) -> 0.020056255 | W79: =IF(U79>0, 1, 0) -> 1
A80: ORD_000079 | B80: CUST_00694 | C80: SKU_0105 | D80: HUB_10 | E80: 45662.94 | F80: 45662.953 | G80: DELIVERED | H80: 3 | I80: 534.51 | J80: 355.26 | K80: 80.18 | L80: 0 | M80: 44.88 | N80: 8.18 | O80: Debit Card | P80: 4 | Q80: 4 | R80: =I80-K80 -> 454.33 | S80: =R80-J80 -> 99.07 | T80: =L80-M80 -> -44.88 | U80: =S80+T80-N80 -> 46.01 | V80: =IF(R80>0, U80/R80, 0) -> 0.10127 | W80: =IF(U80>0, 1, 0) -> 1
A81: ORD_000080 | B81: CUST_00405 | C81: SKU_0199 | D81: HUB_01 | E81: 45663.25 | F81: 45663.263 | G81: DELIVERED | H81: 1 | I81: 547.51 | J81: 328.7 | K81: 54.75 | L81: 0 | M81: 53.38 | N81: 8.87 | O81: UPI | P81: 3 | Q81: 3 | R81: =I81-K81 -> 492.76 | S81: =R81-J81 -> 164.06 | T81: =L81-M81 -> -53.38 | U81: =S81+T81-N81 -> 101.81 | V81: =IF(R81>0, U81/R81, 0) -> 0.20661174 | W81: =IF(U81>0, 1, 0) -> 1
A82: ORD_000081 | B82: CUST_00022 | C82: SKU_0076 | D82: HUB_01 | E82: 45663.306 | F82: 45663.314 | G82: DELIVERED | H82: 5 | I82: 569 | J82: 418.85 | K82: 28.45 | L82: 0 | M82: 59.37 | N82: 9.73 | O82: UPI | P82: 0 | Q82: 5 | R82: =I82-K82 -> 540.55 | S82: =R82-J82 -> 121.7 | T82: =L82-M82 -> -59.37 | U82: =S82+T82-N82 -> 52.6 | V82: =IF(R82>0, U82/R82, 0) -> 0.097308297 | W82: =IF(U82>0, 1, 0) -> 1
A83: ORD_000082 | B83: CUST_00678 | C83: SKU_0165 | D83: HUB_13 | E83: 45663.38 | F83: 45663.403 | G83: DELIVERED | H83: 1 | I83: 234.49 | J83: 139.73 | K83: 0 | L83: 30 | M83: 43.1 | N83: 4.76 | O83: UPI | P83: 13 | Q83: 2 | R83: =I83-K83 -> 234.49 | S83: =R83-J83 -> 94.76 | T83: =L83-M83 -> -13.1 | U83: =S83+T83-N83 -> 76.9 | V83: =IF(R83>0, U83/R83, 0) -> 0.32794575 | W83: =IF(U83>0, 1, 0) -> 1
A84: ORD_000083 | B84: CUST_00611 | C84: SKU_0242 | D84: HUB_13 | E84: 45663.403 | F84: 45663.42 | G84: DELIVERED | H84: 3 | I84: 2096.64 | J84: 1769.07 | K84: 209.66 | L84: 0 | M84: 40.11 | N84: 33.97 | O84: Debit Card | P84: 4 | Q84: 4 | R84: =I84-K84 -> 1886.98 | S84: =R84-J84 -> 117.91 | T84: =L84-M84 -> -40.11 | U84: =S84+T84-N84 -> 43.83 | V84: =IF(R84>0, U84/R84, 0) -> 0.023227591 | W84: =IF(U84>0, 1, 0) -> 1
A85: ORD_000084 | B85: CUST_00008 | C85: SKU_0132 | D85: HUB_10 | E85: 45663.448 | F85: 45663.464 | G85: DELIVERED | H85: 2 | I85: 1795.8 | J85: 1505.36 | K85: 448.95 | L85: 0 | M85: 39.13 | N85: 24.24 | O85: Credit Card | P85: 7 | Q85: 3 | R85: =I85-K85 -> 1346.85 | S85: =R85-J85 -> -158.51 | T85: =L85-M85 -> -39.13 | U85: =S85+T85-N85 -> -221.88 | V85: =IF(R85>0, U85/R85, 0) -> -0.16473995 | W85: =IF(U85>0, 1, 0) -> 0
...

Sheet executive_scenario_model
B2: URBANCART: EXECUTIVE UNIT ECONOMICS & SCENARIO ENGINE
B4: Baseline Portfolio KPIs (Actual 7,000 Orders) | F4: Free-Delivery Threshold Sensitivity Simulation
B5: Total Gross Merchandise Value (GMV) | C5: =SUM(fact_orders!I2:I7001) -> 3994696.6 | F5: Min Basket Size for Free Delivery | G5: Projected Delivery Fee Recovery | H5: Net CM2 Realization | I5: Margin Expansion
B6: Total Promo Discounts Burned | C6: =SUM(fact_orders!K2:K7001) -> 289736.79 | F6: Threshold ₹299 | G6: =C11*1.25 -> -301799.44 | H6: =C13+(G6-C11) -> 391363.52 | I6: =(H6-C13)/C13 -> -0.13362134
B7: Discount Burn Rate (%) | C7: =C6/C5 -> 0.072530361 | F7: Threshold ₹349 | G7: =C11*1.15 -> -277655.48 | H7: =C13+(G7-C11) -> 415507.48 | I7: =(H7-C13)/C13 -> -0.080172804
B8: Net Sales | C8: =SUM(fact_orders!R2:R7001) -> 3704959.9 | F8: Threshold ₹399 | G8: =C11*1 -> -241439.55 | H8: =C13+(G8-C11) -> 451723.41 | I8: =(H8-C13)/C13 -> 0
B9: Total Direct Product Cost (COGS) | C9: =SUM(fact_orders!J2:J7001) -> 2946745.2 | F9: Threshold ₹449 | G9: =C11*0.88 -> -212466.8 | H9: =C13+(G9-C11) -> 480696.16 | I9: =(H9-C13)/C13 -> 0.064138243
B10: Gross Contribution Margin 1 (CM1) | C10: =SUM(fact_orders!S2:S7001) -> 758214.69 | F10: Threshold ₹499 | G10: =C11*0.76 -> -183494.06 | H10: =C13+(G10-C11) -> 509668.9 | I10: =(H10-C13)/C13 -> 0.12827649
B11: Net Logistics Deficit (Delivery Burn) | C11: =SUM(fact_orders!T2:T7001) -> -241439.55
B12: Total Payment Gateway Fees | C12: =SUM(fact_orders!N2:N7001) -> 65051.73
B13: Net Contribution Margin 2 (CM2) | C13: =SUM(fact_orders!U2:U7001) -> 451723.41
B14: Portfolio CM2 Margin (%) | C14: =C13/C8 -> 0.12192397
B15: Order Success Rate (Delivered vs Total) | C15: =COUNTIF(fact_orders!G2:G7001, "DELIVERED")/COUNTA(fact_orders!G2:G7001) -> 0.87014286
B16: Return Leakage Rate | C16: =COUNTIF(fact_orders!G2:G7001, "RETURNED")/COUNTA(fact_orders!G2:G7001) -> 0.078571429
B17: Profitable Order Proportion | C17: =AVERAGE(fact_orders!W2:W7001) -> 0.66685714
